Workbook
Name L_TIPO_CLIENTE: LISTAS!$A$2:$A$5
Name L_ESTADO: LISTAS!$B$2:$B$5
Name L_FORMA: LISTAS!$C$2:$C$5
Name L_ROL: LISTAS!$D$2:$D$3
Name L_CERT: LISTAS!$E$2:$E$5
Name L_SINO: LISTAS!$F$2:$F$3
Name L_TIPO_SUJETO: LISTAS!$G$2:$G$3
Name L_CARGO: LISTAS!$H$2:$H$8
Name L_ESPECIALIDAD: LISTAS!$I$2:$I$23
Name L_ACTIVIDAD: LISTAS!$J$2:$J$8
Name L_UNIDAD: LISTAS!$K$2:$K$11
Name L_DEPARTAMENTO: LISTAS!$L$2:$L$34
Name L_ENTIDAD: CATALOGO_ENTIDADES!$A$2:$A$304

Sheet LEEME
B1: Formato Maestro de Experiencia — Bitácora SECOP (v1)
B2: Un solo formato para registrar la experiencia de empresas y de personas, sin perder información y listo para alimentar el análisis de pliegos.
B4: Cómo está organizado
B5: SUJETOS | C5: Quién tiene la experiencia: una empresa o una persona natural. Un registro por sujeto.
B6: CONTRATOS | C6: Cada contrato UNA sola vez, aunque lo hayan ejecutado varias empresas en consorcio o unión temporal.
B7: PARTICIPACIONES | C7: Qué parte del contrato le corresponde a cada sujeto (porcentaje, forma de ejecución, cargo). Aquí se evita repetir el contrato por empresa.
B8: UNSPSC | C8: Los códigos UNSPSC de cada contrato, uno por fila.
B9: CANTIDADES | C9: Cantidades principales de obra (m², ml, m³...) cuando un pliego las pide.
B10: RESUMEN | C10: Total de experiencia por especialidad para un sujeto (sin contratos en ejecución).
B11: LISTAS · SMMLV · CATALOGO_ENTIDADES | C11: Valores permitidos, salario mínimo por año y nombres únicos de entidades. Aquí se agregan opciones nuevas.
B13: Colores de los encabezados
B14: Rojo — OBLIGATORIO | C14: Sin este dato el contrato no puede analizarse. La celda se marca en rosa si falta.
B15: Naranja — RECOMENDADO | C15: Mejora el análisis (por ejemplo, el departamento o el soporte).
B16: Gris — OPCIONAL | C16: Información útil pero que ningún requisito exige normalmente.
B17: Azul — CALCULADO | C17: No se escribe: lo calcula el libro (plazo, SMMLV, valor actualizado, saldo, alertas).
B19: Reglas
B20: 1. Un contrato, una fila | C20: Si dos archivos traen el mismo contrato con porcentajes distintos, es el mismo contrato: se registra una vez en CONTRATOS y dos veces en PARTICIPACIONES.
B21: 2. Solo números en los valores | C21: Pesos sin "$" ni puntos de texto (use el formato de celda). Porcentajes de 0 % a 100 %. Fechas como fechas (AAAA-MM-DD), nunca como texto ("En Ejecución" va en ESTADO).
B22: 3. Persona ≠ empresa | C22: La experiencia profesional de una persona se registra a su nombre y no se suma a la de la empresa, salvo que usted lo decida.
B23: 4. Contrato en ejecución | C23: No acredita experiencia. Se registra con su valor ejecutado: el saldo alimenta la Capacidad Residual de Bitácora.
B24: 5. Valor actualizado | C24: Se calcula con el SMMLV del año de terminación y el del año de referencia (hoja SMMLV, celda E2). Verifique los años marcados "por verificar".
B25: 6. Entidades | C25: Use siempre el nombre del catálogo. "Gobernación de Santander" y "Gobernación de Norte de Santander" son entidades distintas: no las unifique.
B26: 7. Personas vinculadas | C26: Si la experiencia de una persona natural cuenta para una empresa (por ejemplo, su representante o socio), escriba en CUENTA_PARA de esa persona el ID de la empresa. El RESUMEN y las columnas "CON_VINCULADOS" de SUJETOS la suman; en RESUMEN puede apagar la opción.
B27: 8. Trazabilidad | C27: Anote en ORIGEN el archivo, hoja y fila de donde salió cada contrato, para poder revisarlo contra el original.
B29: Datos de ejemplo | C29: Las filas 2 a 4 de cada hoja son ejemplos FICTICIOS (borrar o reemplazar antes de usar).

Sheet SUJETOS
A1: ID_SUJETO | B1: TIPO | C1: NOMBRE | D1: DOCUMENTO | E1: REGISTRO | F1: CUENTA_PARA | G1: OBSERVACIONES | H1: N_CONTRATOS | I1: VALOR_ACTUALIZADO_TOTAL | J1: N_CONTRATOS_CON_VINCULADOS | K1: VALOR_ACTUALIZADO_CON_VINCULADOS
A2: S-001 | B2: Empresa | C2: CONSTRUCTORA EJEMPLO S.A.S. | D2: 900.000.001-1 | E2: RUP 0001 | G2: Ejemplo ficticio | H2: =IF(A2="","",COUNTIF(PARTICIPACIONES!$B$2:$B$601,A2)) | I2: =IF(A2="","",SUMIFS(PARTICIPACIONES!$M$2:$M$601,PARTICIPACIONES!$B$2:$B$601,A2,PARTICIPACIONES!$P$2:$P$601,"<>En ejecución")) | J2: =IF(A2="","",H2+SUMIF($F$2:$F$601,A2,$H$2:$H$601)) | K2: =IF(A2="","",I2+SUMIF($F$2:$F$601,A2,$I$2:$I$601))
A3: S-002 | B3: Persona natural | C3: María Ejemplo Pérez | D3: 1.000.000.001 | E3: Mat. prof. 00-0001 | F3: S-001 | G3: Ejemplo ficticio: ingeniera vinculada a la empresa; su experiencia cuenta para S-001 | H3: =IF(A3="","",COUNTIF(PARTICIPACIONES!$B$2:$B$601,A3)) | I3: =IF(A3="","",SUMIFS(PARTICIPACIONES!$M$2:$M$601,PARTICIPACIONES!$B$2:$B$601,A3,PARTICIPACIONES!$P$2:$P$601,"<>En ejecución")) | J3: =IF(A3="","",H3+SUMIF($F$2:$F$601,A3,$H$2:$H$601)) | K3: =IF(A3="","",I3+SUMIF($F$2:$F$601,A3,$I$2:$I$601))
A4: S-003 | B4: Empresa | C4: INGENIERÍA DE MUESTRA LTDA. | D4: 900.000.002-2 | E4: RUP 0002 | G4: Ejemplo ficticio | H4: =IF(A4="","",COUNTIF(PARTICIPACIONES!$B$2:$B$601,A4)) | I4: =IF(A4="","",SUMIFS(PARTICIPACIONES!$M$2:$M$601,PARTICIPACIONES!$B$2:$B$601,A4,PARTICIPACIONES!$P$2:$P$601,"<>En ejecución")) | J4: =IF(A4="","",H4+SUMIF($F$2:$F$601,A4,$H$2:$H$601)) | K4: =IF(A4="","",I4+SUMIF($F$2:$F$601,A4,$I$2:$I$601))
H5: =IF(A5="","",COUNTIF(PARTICIPACIONES!$B$2:$B$601,A5)) | I5: =IF(A5="","",SUMIFS(PARTICIPACIONES!$M$2:$M$601,PARTICIPACIONES!$B$2:$B$601,A5,PARTICIPACIONES!$P$2:$P$601,"<>En ejecución")) | J5: =IF(A5="","",H5+SUMIF($F$2:$F$601,A5,$H$2:$H$601)) | K5: =IF(A5="","",I5+SUMIF($F$2:$F$601,A5,$I$2:$I$601))
H6: =IF(A6="","",COUNTIF(PARTICIPACIONES!$B$2:$B$601,A6)) | I6: =IF(A6="","",SUMIFS(PARTICIPACIONES!$M$2:$M$601,PARTICIPACIONES!$B$2:$B$601,A6,PARTICIPACIONES!$P$2:$P$601,"<>En ejecución")) | J6: =IF(A6="","",H6+SUMIF($F$2:$F$601,A6,$H$2:$H$601)) | K6: =IF(A6="","",I6+SUMIF($F$2:$F$601,A6,$I$2:$I$601))
H7: =IF(A7="","",COUNTIF(PARTICIPACIONES!$B$2:$B$601,A7)) | I7: =IF(A7="","",SUMIFS(PARTICIPACIONES!$M$2:$M$601,PARTICIPACIONES!$B$2:$B$601,A7,PARTICIPACIONES!$P$2:$P$601,"<>En ejecución")) | J7: =IF(A7="","",H7+SUMIF($F$2:$F$601,A7,$H$2:$H$601)) | K7: =IF(A7="","",I7+SUMIF($F$2:$F$601,A7,$I$2:$I$601))
H8: =IF(A8="","",COUNTIF(PARTICIPACIONES!$B$2:$B$601,A8)) | I8: =IF(A8="","",SUMIFS(PARTICIPACIONES!$M$2:$M$601,PARTICIPACIONES!$B$2:$B$601,A8,PARTICIPACIONES!$P$2:$P$601,"<>En ejecución")) | J8: =IF(A8="","",H8+SUMIF($F$2:$F$601,A8,$H$2:$H$601)) | K8: =IF(A8="","",I8+SUMIF($F$2:$F$601,A8,$I$2:$I$601))
H9: =IF(A9="","",COUNTIF(PARTICIPACIONES!$B$2:$B$601,A9)) | I9: =IF(A9="","",SUMIFS(PARTICIPACIONES!$M$2:$M$601,PARTICIPACIONES!$B$2:$B$601,A9,PARTICIPACIONES!$P$2:$P$601,"<>En ejecución")) | J9: =IF(A9="","",H9+SUMIF($F$2:$F$601,A9,$H$2:$H$601)) | K9: =IF(A9="","",I9+SUMIF($F$2:$F$601,A9,$I$2:$I$601))
H10: =IF(A10="","",COUNTIF(PARTICIPACIONES!$B$2:$B$601,A10)) | I10: =IF(A10="","",SUMIFS(PARTICIPACIONES!$M$2:$M$601,PARTICIPACIONES!$B$2:$B$601,A10,PARTICIPACIONES!$P$2:$P$601,"<>En ejecución")) | J10: =IF(A10="","",H10+SUMIF($F$2:$F$601,A10,$H$2:$H$601)) | K10: =IF(A10="","",I10+SUMIF($F$2:$F$601,A10,$I$2:$I$601))
H11: =IF(A11="","",COUNTIF(PARTICIPACIONES!$B$2:$B$601,A11)) | I11: =IF(A11="","",SUMIFS(PARTICIPACIONES!$M$2:$M$601,PARTICIPACIONES!$B$2:$B$601,A11,PARTICIPACIONES!$P$2:$P$601,"<>En ejecución")) | J11: =IF(A11="","",H11+SUMIF($F$2:$F$601,A11,$H$2:$H$601)) | K11: =IF(A11="","",I11+SUMIF($F$2:$F$601,A11,$I$2:$I$601))
H12: =IF(A12="","",COUNTIF(PARTICIPACIONES!$B$2:$B$601,A12)) | I12: =IF(A12="","",SUMIFS(PARTICIPACIONES!$M$2:$M$601,PARTICIPACIONES!$B$2:$B$601,A12,PARTICIPACIONES!$P$2:$P$601,"<>En ejecución")) | J12: =IF(A12="","",H12+SUMIF($F$2:$F$601,A12,$H$2:$H$601)) | K12: =IF(A12="","",I12+SUMIF($F$2:$F$601,A12,$I$2:$I$601))
H13: =IF(A13="","",COUNTIF(PARTICIPACIONES!$B$2:$B$601,A13)) | I13: =IF(A13="","",SUMIFS(PARTICIPACIONES!$M$2:$M$601,PARTICIPACIONES!$B$2:$B$601,A13,PARTICIPACIONES!$P$2:$P$601,"<>En ejecución")) | J13: =IF(A13="","",H13+SUMIF($F$2:$F$601,A13,$H$2:$H$601)) | K13: =IF(A13="","",I13+SUMIF($F$2:$F$601,A13,$I$2:$I$601))
H14: =IF(A14="","",COUNTIF(PARTICIPACIONES!$B$2:$B$601,A14)) | I14: =IF(A14="","",SUMIFS(PARTICIPACIONES!$M$2:$M$601,PARTICIPACIONES!$B$2:$B$601,A14,PARTICIPACIONES!$P$2:$P$601,"<>En ejecución")) | J14: =IF(A14="","",H14+SUMIF($F$2:$F$601,A14,$H$2:$H$601)) | K14: =IF(A14="","",I14+SUMIF($F$2:$F$601,A14,$I$2:$I$601))
H15: =IF(A15="","",COUNTIF(PARTICIPACIONES!$B$2:$B$601,A15)) | I15: =IF(A15="","",SUMIFS(PARTICIPACIONES!$M$2:$M$601,PARTICIPACIONES!$B$2:$B$601,A15,PARTICIPACIONES!$P$2:$P$601,"<>En ejecución")) | J15: =IF(A15="","",H15+SUMIF($F$2:$F$601,A15,$H$2:$H$601)) | K15: =IF(A15="","",I15+SUMIF($F$2:$F$601,A15,$I$2:$I$601))
H16: =IF(A16="","",COUNTIF(PARTICIPACIONES!$B$2:$B$601,A16)) | I16: =IF(A16="","",SUMIFS(PARTICIPACIONES!$M$2:$M$601,PARTICIPACIONES!$B$2:$B$601,A16,PARTICIPACIONES!$P$2:$P$601,"<>En ejecución")) | J16: =IF(A16="","",H16+SUMIF($F$2:$F$601,A16,$H$2:$H$601)) | K16: =IF(A16="","",I16+SUMIF($F$2:$F$601,A16,$I$2:$I$601))
... H601: =IF(A601="","",COUNTIF(PARTICIPACIONES!$B$2:$B$601,A601)) | I601: =IF(A601="","",SUMIFS(PARTICIPACIONES!$M$2:$M$601,PARTICIPACIONES!$B$2:$B$601,A601,PARTICIPACIONES!$P$2:$P$601,"<>En ejecución")) | J601: =IF(A601="","",H601+SUMIF($F$2:$F$601,A601,$H$2:$H$601)) | K601: =IF(A601="","",I601+SUMIF($F$2:$F$601,A601,$I$2:$I$601))

Sheet CONTRATOS
A1: ID_CONTRATO | B1: NUMERO_CONTRATO | C1: ENTIDAD | D1: TIPO_CLIENTE | E1: OBJETO | F1: ESPECIALIDAD | G1: TIPO_ACTIVIDAD | H1: DEPARTAMENTO | I1: MUNICIPIO | J1: FECHA_SUSCRIPCION | K1: FECHA_INICIO | L1: FECHA_TERMINACION | M1: ESTADO | N1: FECHA_LIQUIDACION | O1: VALOR_INICIAL | P1: VALOR_CONTRATO | Q1: VALOR_EJECUTADO | R1: NUMERO_EN_RUP | S1: SOPORTE | T1: INTERVENTOR | U1: OBSERVACIONES | V1: ORIGEN | W1: PLAZO_MESES | X1: ANO_SMMLV | Y1: SMMLV_DEL_ANO | Z1: VALOR_EN_SMMLV | AA1: VALOR_ACTUALIZADO | AB1: SALDO_PENDIENTE | AC1: ALERTAS
A2: C-0001 | B2: 001/2015 | C2: Alcaldía de Ejemplo | D2: Público | E2: CONSTRUCCIÓN DE AULA Y BATERÍA SANITARIA EN LA INSTITUCIÓN EDUCATIVA EJEMPLO, MUNICIPIO DE EJEMPLO | F2: Edificaciones educativas | G2: Construcción | H2: Norte de Santander | I2: Ejemplo | K2: 42009 | L2: 42066 | M2: Terminado | P2: 163147838 | R2: 12 | U2: Ejemplo ficticio: dos integrantes en unión temporal (90 % y 10 %). Un contrato, dos participaciones. | V2: Archivo ejemplo › hoja 1 fila 5 | W2: =IF(AND(K2<>"",L2<>""),ROUND((L2-K2)/30.4375,1),"") | X2: =IF(OR(A2="",M2="En ejecución",L2=""),"",YEAR(L2)) | Y2: =IF(X2="","",IFERROR(VLOOKUP(X2,SMMLV!$A$2:$B$38,2,FALSE),"")) | Z2: =IF(OR(Y2="",P2=""),"",ROUND(P2/Y2,2)) | AA2: =IF(Z2="","",ROUND(Z2*SMMLV!$E$4,0)) | AB2: =IF(AND(M2="En ejecución",P2<>"",Q2<>""),MAX(P2-Q2,0),"") | AC2: =IF(A2="","",IF(B2="","Falta número de contrato; ","")&IF(C2="","Falta entidad; ","")&IF(E2="","Falta objeto; ","")&IF(F2="","Falta especialidad; ","")&IF(K2="","Falta fecha de inicio (recomendada); ","")&IF(AND(M2<>"En ejecución",L2=""),"Falta fecha de terminación; ","")&IF(AND(K2<>"",L2<>"",L2<K2),"Terminación anterior al inicio; ","")&IF(M2="","Falta estado; ","")&IF(OR(P2="",P2<=0),"Falta valor del contrato; ","")&IF(AND(M2="En ejecución",Q2=""),"En ejecución sin valor ejecutado; ","")&IF(AND(M2="En ejecución",L2<>"",L2<TODAY()),"Dice en ejecución pero su terminación ya pasó; ","")&IF(M2="En ejecución","En ejecución: no acredita experiencia; ","")&IF(AND(M2<>"En ejecución",L2<>"",X2<>"",Y2=""),"El año no está en la hoja SMMLV; ","")&IF(AND(B2<>"",COUNTIFS($B$2:$B$601,B2,$C$2:$C$601,C2)>1),"Posible duplicado (mismo número y entidad); ","")&IF(COUNTIF(PARTICIPACIONES!$A$2:$A$601,A2)=0,"Sin participaciones; ","")&IF(SUMIFS(PARTICIPACIONES!$E$2:$E$601,PARTICIPACIONES!$A$2:$A$601,A2)>1.0001,"Las participaciones suman más de 100 %; ",""))
A3: C-0002 | B3: S/N | C3: Gobernación de Ejemplo | D3: Público | E3: MANTENIMIENTO DE VÍA TERCIARIA ENTRE LA VEREDA A Y LA VEREDA B | F3: Vías y carreteras | G3: Mantenimiento | H3: Norte de Santander | I3: Ejemplo | K3: 43617 | L3: 43738 | M3: Liquidado | N3: 43845 | P3: 520000000 | S3: Acta de liquidación 2020 | U3: Ejemplo ficticio: contrato individual, sin número (S/N). | V3: Archivo ejemplo › hoja 1 fila 6 | W3: =IF(AND(K3<>"",L3<>""),ROUND((L3-K3)/30.4375,1),"") | X3: =IF(OR(A3="",M3="En ejecución",L3=""),"",YEAR(L3)) | Y3: =IF(X3="","",IFERROR(VLOOKUP(X3,SMMLV!$A$2:$B$38,2,FALSE),"")) | Z3: =IF(OR(Y3="",P3=""),"",ROUND(P3/Y3,2)) | AA3: =IF(Z3="","",ROUND(Z3*SMMLV!$E$4,0)) | AB3: =IF(AND(M3="En ejecución",P3<>"",Q3<>""),MAX(P3-Q3,0),"") | AC3: =IF(A3="","",IF(B3="","Falta número de contrato; ","")&IF(C3="","Falta entidad; ","")&IF(E3="","Falta objeto; ","")&IF(F3="","Falta especialidad; ","")&IF(K3="","Falta fecha de inicio (recomendada); ","")&IF(AND(M3<>"En ejecución",L3=""),"Falta fecha de terminación; ","")&IF(AND(K3<>"",L3<>"",L3<K3),"Terminación anterior al inicio; ","")&IF(M3="","Falta estado; ","")&IF(OR(P3="",P3<=0),"Falta valor del contrato; ","")&IF(AND(M3="En ejecución",Q3=""),"En ejecución sin valor ejecutado; ","")&IF(AND(M3="En ejecución",L3<>"",L3<TODAY()),"Dice en ejecución pero su terminación ya pasó; ","")&IF(M3="En ejecución","En ejecución: no acredita experiencia; ","")&IF(AND(M3<>"En ejecución",L3<>"",X3<>"",Y3=""),"El año no está en la hoja SMMLV; ","")&IF(AND(B3<>"",COUNTIFS($B$2:$B$601,B3,$C$2:$C$601,C3)>1),"Posible duplicado (mismo número y entidad); ","")&IF(COUNTIF(PARTICIPACIONES!$A$2:$A$601,A3)=0,"Sin participaciones; ","")&IF(SUMIFS(PARTICIPACIONES!$E$2:$E$601,PARTICIPACIONES!$A$2:$A$601,A3)>1.0001,"Las participaciones suman más de 100 %; ",""))
A4: C-0003 | B4: GG-4215-2020 | C4: Empresa de Gas de Ejemplo S.A. E.S.P. | D4: Privado | E4: TRASLADO DE TUBERÍA ADOSADA EN EL PUENTE EJEMPLO, MUNICIPIO DE EJEMPLO | F4: Redes de gas | G4: Suministro e instalación | H4: Huila | I4: Ejemplo | J4: 44057 | K4: 44476 | M4: En ejecución | P4: 422642613 | Q4: 150000000 | U4: Ejemplo ficticio de contrato EN EJECUCIÓN: no acredita experiencia; su saldo descuenta capacidad residual. | V4: Archivo ejemplo › hoja 1 fila 7 | W4: =IF(AND(K4<>"",L4<>""),ROUND((L4-K4)/30.4375,1),"") | X4: =IF(OR(A4="",M4="En ejecución",L4=""),"",YEAR(L4)) | Y4: =IF(X4="","",IFERROR(VLOOKUP(X4,SMMLV!$A$2:$B$38,2,FALSE),"")) | Z4: =IF(OR(Y4="",P4=""),"",ROUND(P4/Y4,2)) | AA4: =IF(Z4="","",ROUND(Z4*SMMLV!$E$4,0)) | AB4: =IF(AND(M4="En ejecución",P4<>"",Q4<>""),MAX(P4-Q4,0),"") | AC4: =IF(A4="","",IF(B4="","Falta número de contrato; ","")&IF(C4="","Falta entidad; ","")&IF(E4="","Falta objeto; ","")&IF(F4="","Falta especialidad; ","")&IF(K4="","Falta fecha de inicio (recomendada); ","")&IF(AND(M4<>"En ejecución",L4=""),"Falta fecha de terminación; ","")&IF(AND(K4<>"",L4<>"",L4<K4),"Terminación anterior al inicio; ","")&IF(M4="","Falta estado; ","")&IF(OR(P4="",P4<=0),"Falta valor del contrato; ","")&IF(AND(M4="En ejecución",Q4=""),"En ejecución sin valor ejecutado; ","")&IF(AND(M4="En ejecución",L4<>"",L4<TODAY()),"Dice en ejecución pero su terminación ya pasó; ","")&IF(M4="En ejecución","En ejecución: no acredita experiencia; ","")&IF(AND(M4<>"En ejecución",L4<>"",X4<>"",Y4=""),"El año no está en la hoja SMMLV; ","")&IF(AND(B4<>"",COUNTIFS($B$2:$B$601,B4,$C$2:$C$601,C4)>1),"Posible duplicado (mismo número y entidad); ","")&IF(COUNTIF(PARTICIPACIONES!$A$2:$A$601,A4)=0,"Sin participaciones; ","")&IF(SUMIFS(PARTICIPACIONES!$E$2:$E$601,PARTICIPACIONES!$A$2:$A$601,A4)>1.0001,"Las participaciones suman más de 100 %; ",""))
W5: =IF(AND(K5<>"",L5<>""),ROUND((L5-K5)/30.4375,1),"") | X5: =IF(OR(A5="",M5="En ejecución",L5=""),"",YEAR(L5)) | Y5: =IF(X5="","",IFERROR(VLOOKUP(X5,SMMLV!$A$2:$B$38,2,FALSE),"")) | Z5: =IF(OR(Y5="",P5=""),"",ROUND(P5/Y5,2)) | AA5: =IF(Z5="","",ROUND(Z5*SMMLV!$E$4,0)) | AB5: =IF(AND(M5="En ejecución",P5<>"",Q5<>""),MAX(P5-Q5,0),"") | AC5: =IF(A5="","",IF(B5="","Falta número de contrato; ","")&IF(C5="","Falta entidad; ","")&IF(E5="","Falta objeto; ","")&IF(F5="","Falta especialidad; ","")&IF(K5="","Falta fecha de inicio (recomendada); ","")&IF(AND(M5<>"En ejecución",L5=""),"Falta fecha de terminación; ","")&IF(AND(K5<>"",L5<>"",L5<K5),"Terminación anterior al inicio; ","")&IF(M5="","Falta estado; ","")&IF(OR(P5="",P5<=0),"Falta valor del contrato; ","")&IF(AND(M5="En ejecución",Q5=""),"En ejecución sin valor ejecutado; ","")&IF(AND(M5="En ejecución",L5<>"",L5<TODAY()),"Dice en ejecución pero su terminación ya pasó; ","")&IF(M5="En ejecución","En ejecución: no acredita experiencia; ","")&IF(AND(M5<>"En ejecución",L5<>"",X5<>"",Y5=""),"El año no está en la hoja SMMLV; ","")&IF(AND(B5<>"",COUNTIFS($B$2:$B$601,B5,$C$2:$C$601,C5)>1),"Posible duplicado (mismo número y entidad); ","")&IF(COUNTIF(PARTICIPACIONES!$A$2:$A$601,A5)=0,"Sin participaciones; ","")&IF(SUMIFS(PARTICIPACIONES!$E$2:$E$601,PARTICIPACIONES!$A$2:$A$601,A5)>1.0001,"Las participaciones suman más de 100 %; ",""))
W6: =IF(AND(K6<>"",L6<>""),ROUND((L6-K6)/30.4375,1),"") | X6: =IF(OR(A6="",M6="En ejecución",L6=""),"",YEAR(L6)) | Y6: =IF(X6="","",IFERROR(VLOOKUP(X6,SMMLV!$A$2:$B$38,2,FALSE),"")) | Z6: =IF(OR(Y6="",P6=""),"",ROUND(P6/Y6,2)) | AA6: =IF(Z6="","",ROUND(Z6*SMMLV!$E$4,0)) | AB6: =IF(AND(M6="En ejecución",P6<>"",Q6<>""),MAX(P6-Q6,0),"") | AC6: =IF(A6="","",IF(B6="","Falta número de contrato; ","")&IF(C6="","Falta entidad; ","")&IF(E6="","Falta objeto; ","")&IF(F6="","Falta especialidad; ","")&IF(K6="","Falta fecha de inicio (recomendada); ","")&IF(AND(M6<>"En ejecución",L6=""),"Falta fecha de terminación; ","")&IF(AND(K6<>"",L6<>"",L6<K6),"Terminación anterior al inicio; ","")&IF(M6="","Falta estado; ","")&IF(OR(P6="",P6<=0),"Falta valor del contrato; ","")&IF(AND(M6="En ejecución",Q6=""),"En ejecución sin valor ejecutado; ","")&IF(AND(M6="En ejecución",L6<>"",L6<TODAY()),"Dice en ejecución pero su terminación ya pasó; ","")&IF(M6="En ejecución","En ejecución: no acredita experiencia; ","")&IF(AND(M6<>"En ejecución",L6<>"",X6<>"",Y6=""),"El año no está en la hoja SMMLV; ","")&IF(AND(B6<>"",COUNTIFS($B$2:$B$601,B6,$C$2:$C$601,C6)>1),"Posible duplicado (mismo número y entidad); ","")&IF(COUNTIF(PARTICIPACIONES!$A$2:$A$601,A6)=0,"Sin participaciones; ","")&IF(SUMIFS(PARTICIPACIONES!$E$2:$E$601,PARTICIPACIONES!$A$2:$A$601,A6)>1.0001,"Las participaciones suman más de 100 %; ",""))
W7: =IF(AND(K7<>"",L7<>""),ROUND((L7-K7)/30.4375,1),"") | X7: =IF(OR(A7="",M7="En ejecución",L7=""),"",YEAR(L7)) | Y7: =IF(X7="","",IFERROR(VLOOKUP(X7,SMMLV!$A$2:$B$38,2,FALSE),"")) | Z7: =IF(OR(Y7="",P7=""),"",ROUND(P7/Y7,2)) | AA7: =IF(Z7="","",ROUND(Z7*SMMLV!$E$4,0)) | AB7: =IF(AND(M7="En ejecución",P7<>"",Q7<>""),MAX(P7-Q7,0),"") | AC7: =IF(A7="","",IF(B7="","Falta número de contrato; ","")&IF(C7="","Falta entidad; ","")&IF(E7="","Falta objeto; ","")&IF(F7="","Falta especialidad; ","")&IF(K7="","Falta fecha de inicio (recomendada); ","")&IF(AND(M7<>"En ejecución",L7=""),"Falta fecha de terminación; ","")&IF(AND(K7<>"",L7<>"",L7<K7),"Terminación anterior al inicio; ","")&IF(M7="","Falta estado; ","")&IF(OR(P7="",P7<=0),"Falta valor del contrato; ","")&IF(AND(M7="En ejecución",Q7=""),"En ejecución sin valor ejecutado; ","")&IF(AND(M7="En ejecución",L7<>"",L7<TODAY()),"Dice en ejecución pero su terminación ya pasó; ","")&IF(M7="En ejecución","En ejecución: no acredita experiencia; ","")&IF(AND(M7<>"En ejecución",L7<>"",X7<>"",Y7=""),"El año no está en la hoja SMMLV; ","")&IF(AND(B7<>"",COUNTIFS($B$2:$B$601,B7,$C$2:$C$601,C7)>1),"Posible duplicado (mismo número y entidad); ","")&IF(COUNTIF(PARTICIPACIONES!$A$2:$A$601,A7)=0,"Sin participaciones; ","")&IF(SUMIFS(PARTICIPACIONES!$E$2:$E$601,PARTICIPACIONES!$A$2:$A$601,A7)>1.0001,"Las participaciones suman más de 100 %; ",""))
W8: =IF(AND(K8<>"",L8<>""),ROUND((L8-K8)/30.4375,1),"") | X8: =IF(OR(A8="",M8="En ejecución",L8=""),"",YEAR(L8)) | Y8: =IF(X8="","",IFERROR(VLOOKUP(X8,SMMLV!$A$2:$B$38,2,FALSE),"")) | Z8: =IF(OR(Y8="",P8=""),"",ROUND(P8/Y8,2)) | AA8: =IF(Z8="","",ROUND(Z8*SMMLV!$E$4,0)) | AB8: =IF(AND(M8="En ejecución",P8<>"",Q8<>""),MAX(P8-Q8,0),"") | AC8: =IF(A8="","",IF(B8="","Falta número de contrato; ","")&IF(C8="","Falta entidad; ","")&IF(E8="","Falta objeto; ","")&IF(F8="","Falta especialidad; ","")&IF(K8="","Falta fecha de inicio (recomendada); ","")&IF(AND(M8<>"En ejecución",L8=""),"Falta fecha de terminación; ","")&IF(AND(K8<>"",L8<>"",L8<K8),"Terminación anterior al inicio; ","")&IF(M8="","Falta estado; ","")&IF(OR(P8="",P8<=0),"Falta valor del contrato; ","")&IF(AND(M8="En ejecución",Q8=""),"En ejecución sin valor ejecutado; ","")&IF(AND(M8="En ejecución",L8<>"",L8<TODAY()),"Dice en ejecución pero su terminación ya pasó; ","")&IF(M8="En ejecución","En ejecución: no acredita experiencia; ","")&IF(AND(M8<>"En ejecución",L8<>"",X8<>"",Y8=""),"El año no está en la hoja SMMLV; ","")&IF(AND(B8<>"",COUNTIFS($B$2:$B$601,B8,$C$2:$C$601,C8)>1),"Posible duplicado (mismo número y entidad); ","")&IF(COUNTIF(PARTICIPACIONES!$A$2:$A$601,A8)=0,"Sin participaciones; ","")&IF(SUMIFS(PARTICIPACIONES!$E$2:$E$601,PARTICIPACIONES!$A$2:$A$601,A8)>1.0001,"Las participaciones suman más de 100 %; ",""))
W9: =IF(AND(K9<>"",L9<>""),ROUND((L9-K9)/30.4375,1),"") | X9: =IF(OR(A9="",M9="En ejecución",L9=""),"",YEAR(L9)) | Y9: =IF(X9="","",IFERROR(VLOOKUP(X9,SMMLV!$A$2:$B$38,2,FALSE),"")) | Z9: =IF(OR(Y9="",P9=""),"",ROUND(P9/Y9,2)) | AA9: =IF(Z9="","",ROUND(Z9*SMMLV!$E$4,0)) | AB9: =IF(AND(M9="En ejecución",P9<>"",Q9<>""),MAX(P9-Q9,0),"") | AC9: =IF(A9="","",IF(B9="","Falta número de contrato; ","")&IF(C9="","Falta entidad; ","")&IF(E9="","Falta objeto; ","")&IF(F9="","Falta especialidad; ","")&IF(K9="","Falta fecha de inicio (recomendada); ","")&IF(AND(M9<>"En ejecución",L9=""),"Falta fecha de terminación; ","")&IF(AND(K9<>"",L9<>"",L9<K9),"Terminación anterior al inicio; ","")&IF(M9="","Falta estado; ","")&IF(OR(P9="",P9<=0),"Falta valor del contrato; ","")&IF(AND(M9="En ejecución",Q9=""),"En ejecución sin valor ejecutado; ","")&IF(AND(M9="En ejecución",L9<>"",L9<TODAY()),"Dice en ejecución pero su terminación ya pasó; ","")&IF(M9="En ejecución","En ejecución: no acredita experiencia; ","")&IF(AND(M9<>"En ejecución",L9<>"",X9<>"",Y9=""),"El año no está en la hoja SMMLV; ","")&IF(AND(B9<>"",COUNTIFS($B$2:$B$601,B9,$C$2:$C$601,C9)>1),"Posible duplicado (mismo número y entidad); ","")&IF(COUNTIF(PARTICIPACIONES!$A$2:$A$601,A9)=0,"Sin participaciones; ","")&IF(SUMIFS(PARTICIPACIONES!$E$2:$E$601,PARTICIPACIONES!$A$2:$A$601,A9)>1.0001,"Las participaciones suman más de 100 %; ",""))
W10: =IF(AND(K10<>"",L10<>""),ROUND((L10-K10)/30.4375,1),"") | X10: =IF(OR(A10="",M10="En ejecución",L10=""),"",YEAR(L10)) | Y10: =IF(X10="","",IFERROR(VLOOKUP(X10,SMMLV!$A$2:$B$38,2,FALSE),"")) | Z10: =IF(OR(Y10="",P10=""),"",ROUND(P10/Y10,2)) | AA10: =IF(Z10="","",ROUND(Z10*SMMLV!$E$4,0)) | AB10: =IF(AND(M10="En ejecución",P10<>"",Q10<>""),MAX(P10-Q10,0),"") | AC10: =IF(A10="","",IF(B10="","Falta número de contrato; ","")&IF(C10="","Falta entidad; ","")&IF(E10="","Falta objeto; ","")&IF(F10="","Falta especialidad; ","")&IF(K10="","Falta fecha de inicio (recomendada); ","")&IF(AND(M10<>"En ejecución",L10=""),"Falta fecha de terminación; ","")&IF(AND(K10<>"",L10<>"",L10<K10),"Terminación anterior al inicio; ","")&IF(M10="","Falta estado; ","")&IF(OR(P10="",P10<=0),"Falta valor del contrato; ","")&IF(AND(M10="En ejecución",Q10=""),"En ejecución sin valor ejecutado; ","")&IF(AND(M10="En ejecución",L10<>"",L10<TODAY()),"Dice en ejecución pero su terminación ya pasó; ","")&IF(M10="En ejecución","En ejecución: no acredita experiencia; ","")&IF(AND(M10<>"En ejecución",L10<>"",X10<>"",Y10=""),"El año no está en la hoja SMMLV; ","")&IF(AND(B10<>"",COUNTIFS($B$2:$B$601,B10,$C$2:$C$601,C10)>1),"Posible duplicado (mismo número y entidad); ","")&IF(COUNTIF(PARTICIPACIONES!$A$2:$A$601,A10)=0,"Sin participaciones; ","")&IF(SUMIFS(PARTICIPACIONES!$E$2:$E$601,PARTICIPACIONES!$A$2:$A$601,A10)>1.0001,"Las participaciones suman más de 100 %; ",""))
W11: =IF(AND(K11<>"",L11<>""),ROUND((L11-K11)/30.4375,1),"") | X11: =IF(OR(A11="",M11="En ejecución",L11=""),"",YEAR(L11)) | Y11: =IF(X11="","",IFERROR(VLOOKUP(X11,SMMLV!$A$2:$B$38,2,FALSE),"")) | Z11: =IF(OR(Y11="",P11=""),"",ROUND(P11/Y11,2)) | AA11: =IF(Z11="","",ROUND(Z11*SMMLV!$E$4,0)) | AB11: =IF(AND(M11="En ejecución",P11<>"",Q11<>""),MAX(P11-Q11,0),"") | AC11: =IF(A11="","",IF(B11="","Falta número de contrato; ","")&IF(C11="","Falta entidad; ","")&IF(E11="","Falta objeto; ","")&IF(F11="","Falta especialidad; ","")&IF(K11="","Falta fecha de inicio (recomendada); ","")&IF(AND(M11<>"En ejecución",L11=""),"Falta fecha de terminación; ","")&IF(AND(K11<>"",L11<>"",L11<K11),"Terminación anterior al inicio; ","")&IF(M11="","Falta estado; ","")&IF(OR(P11="",P11<=0),"Falta valor del contrato; ","")&IF(AND(M11="En ejecución",Q11=""),"En ejecución sin valor ejecutado; ","")&IF(AND(M11="En ejecución",L11<>"",L11<TODAY()),"Dice en ejecución pero su terminación ya pasó; ","")&IF(M11="En ejecución","En ejecución: no acredita experiencia; ","")&IF(AND(M11<>"En ejecución",L11<>"",X11<>"",Y11=""),"El año no está en la hoja SMMLV; ","")&IF(AND(B11<>"",COUNTIFS($B$2:$B$601,B11,$C$2:$C$601,C11)>1),"Posible duplicado (mismo número y entidad); ","")&IF(COUNTIF(PARTICIPACIONES!$A$2:$A$601,A11)=0,"Sin participaciones; ","")&IF(SUMIFS(PARTICIPACIONES!$E$2:$E$601,PARTICIPACIONES!$A$2:$A$601,A11)>1.0001,"Las participaciones suman más de 100 %; ",""))
W12: =IF(AND(K12<>"",L12<>""),ROUND((L12-K12)/30.4375,1),"") | X12: =IF(OR(A12="",M12="En ejecución",L12=""),"",YEAR(L12)) | Y12: =IF(X12="","",IFERROR(VLOOKUP(X12,SMMLV!$A$2:$B$38,2,FALSE),"")) | Z12: =IF(OR(Y12="",P12=""),"",ROUND(P12/Y12,2)) | AA12: =IF(Z12="","",ROUND(Z12*SMMLV!$E$4,0)) | AB12: =IF(AND(M12="En ejecución",P12<>"",Q12<>""),MAX(P12-Q12,0),"") | AC12: =IF(A12="","",IF(B12="","Falta número de contrato; ","")&IF(C12="","Falta entidad; ","")&IF(E12="","Falta objeto; ","")&IF(F12="","Falta especialidad; ","")&IF(K12="","Falta fecha de inicio (recomendada); ","")&IF(AND(M12<>"En ejecución",L12=""),"Falta fecha de terminación; ","")&IF(AND(K12<>"",L12<>"",L12<K12),"Terminación anterior al inicio; ","")&IF(M12="","Falta estado; ","")&IF(OR(P12="",P12<=0),"Falta valor del contrato; ","")&IF(AND(M12="En ejecución",Q12=""),"En ejecución sin valor ejecutado; ","")&IF(AND(M12="En ejecución",L12<>"",L12<TODAY()),"Dice en ejecución pero su terminación ya pasó; ","")&IF(M12="En ejecución","En ejecución: no acredita experiencia; ","")&IF(AND(M12<>"En ejecución",L12<>"",X12<>"",Y12=""),"El año no está en la hoja SMMLV; ","")&IF(AND(B12<>"",COUNTIFS($B$2:$B$601,B12,$C$2:$C$601,C12)>1),"Posible duplicado (mismo número y entidad); ","")&IF(COUNTIF(PARTICIPACIONES!$A$2:$A$601,A12)=0,"Sin participaciones; ","")&IF(SUMIFS(PARTICIPACIONES!$E$2:$E$601,PARTICIPACIONES!$A$2:$A$601,A12)>1.0001,"Las participaciones suman más de 100 %; ",""))
W13: =IF(AND(K13<>"",L13<>""),ROUND((L13-K13)/30.4375,1),"") | X13: =IF(OR(A13="",M13="En ejecución",L13=""),"",YEAR(L13)) | Y13: =IF(X13="","",IFERROR(VLOOKUP(X13,SMMLV!$A$2:$B$38,2,FALSE),"")) | Z13: =IF(OR(Y13="",P13=""),"",ROUND(P13/Y13,2)) | AA13: =IF(Z13="","",ROUND(Z13*SMMLV!$E$4,0)) | AB13: =IF(AND(M13="En ejecución",P13<>"",Q13<>""),MAX(P13-Q13,0),"") | AC13: =IF(A13="","",IF(B13="","Falta número de contrato; ","")&IF(C13="","Falta entidad; ","")&IF(E13="","Falta objeto; ","")&IF(F13="","Falta especialidad; ","")&IF(K13="","Falta fecha de inicio (recomendada); ","")&IF(AND(M13<>"En ejecución",L13=""),"Falta fecha de terminación; ","")&IF(AND(K13<>"",L13<>"",L13<K13),"Terminación anterior al inicio; ","")&IF(M13="","Falta estado; ","")&IF(OR(P13="",P13<=0),"Falta valor del contrato; ","")&IF(AND(M13="En ejecución",Q13=""),"En ejecución sin valor ejecutado; ","")&IF(AND(M13="En ejecución",L13<>"",L13<TODAY()),"Dice en ejecución pero su terminación ya pasó; ","")&IF(M13="En ejecución","En ejecución: no acredita experiencia; ","")&IF(AND(M13<>"En ejecución",L13<>"",X13<>"",Y13=""),"El año no está en la hoja SMMLV; ","")&IF(AND(B13<>"",COUNTIFS($B$2:$B$601,B13,$C$2:$C$601,C13)>1),"Posible duplicado (mismo número y entidad); ","")&IF(COUNTIF(PARTICIPACIONES!$A$2:$A$601,A13)=0,"Sin participaciones; ","")&IF(SUMIFS(PARTICIPACIONES!$E$2:$E$601,PARTICIPACIONES!$A$2:$A$601,A13)>1.0001,"Las participaciones suman más de 100 %; ",""))
W14: =IF(AND(K14<>"",L14<>""),ROUND((L14-K14)/30.4375,1),"") | X14: =IF(OR(A14="",M14="En ejecución",L14=""),"",YEAR(L14)) | Y14: =IF(X14="","",IFERROR(VLOOKUP(X14,SMMLV!$A$2:$B$38,2,FALSE),"")) | Z14: =IF(OR(Y14="",P14=""),"",ROUND(P14/Y14,2)) | AA14: =IF(Z14="","",ROUND(Z14*SMMLV!$E$4,0)) | AB14: =IF(AND(M14="En ejecución",P14<>"",Q14<>""),MAX(P14-Q14,0),"") | AC14: =IF(A14="","",IF(B14="","Falta número de contrato; ","")&IF(C14="","Falta entidad; ","")&IF(E14="","Falta objeto; ","")&IF(F14="","Falta especialidad; ","")&IF(K14="","Falta fecha de inicio (recomendada); ","")&IF(AND(M14<>"En ejecución",L14=""),"Falta fecha de terminación; ","")&IF(AND(K14<>"",L14<>"",L14<K14),"Terminación anterior al inicio; ","")&IF(M14="","Falta estado; ","")&IF(OR(P14="",P14<=0),"Falta valor del contrato; ","")&IF(AND(M14="En ejecución",Q14=""),"En ejecución sin valor ejecutado; ","")&IF(AND(M14="En ejecución",L14<>"",L14<TODAY()),"Dice en ejecución pero su terminación ya pasó; ","")&IF(M14="En ejecución","En ejecución: no acredita experiencia; ","")&IF(AND(M14<>"En ejecución",L14<>"",X14<>"",Y14=""),"El año no está en la hoja SMMLV; ","")&IF(AND(B14<>"",COUNTIFS($B$2:$B$601,B14,$C$2:$C$601,C14)>1),"Posible duplicado (mismo número y entidad); ","")&IF(COUNTIF(PARTICIPACIONES!$A$2:$A$601,A14)=0,"Sin participaciones; ","")&IF(SUMIFS(PARTICIPACIONES!$E$2:$E$601,PARTICIPACIONES!$A$2:$A$601,A14)>1.0001,"Las participaciones suman más de 100 %; ",""))
W15: =IF(AND(K15<>"",L15<>""),ROUND((L15-K15)/30.4375,1),"") | X15: =IF(OR(A15="",M15="En ejecución",L15=""),"",YEAR(L15)) | Y15: =IF(X15="","",IFERROR(VLOOKUP(X15,SMMLV!$A$2:$B$38,2,FALSE),"")) | Z15: =IF(OR(Y15="",P15=""),"",ROUND(P15/Y15,2)) | AA15: =IF(Z15="","",ROUND(Z15*SMMLV!$E$4,0)) | AB15: =IF(AND(M15="En ejecución",P15<>"",Q15<>""),MAX(P15-Q15,0),"") | AC15: =IF(A15="","",IF(B15="","Falta número de contrato; ","")&IF(C15="","Falta entidad; ","")&IF(E15="","Falta objeto; ","")&IF(F15="","Falta especialidad; ","")&IF(K15="","Falta fecha de inicio (recomendada); ","")&IF(AND(M15<>"En ejecución",L15=""),"Falta fecha de terminación; ","")&IF(AND(K15<>"",L15<>"",L15<K15),"Terminación anterior al inicio; ","")&IF(M15="","Falta estado; ","")&IF(OR(P15="",P15<=0),"Falta valor del contrato; ","")&IF(AND(M15="En ejecución",Q15=""),"En ejecución sin valor ejecutado; ","")&IF(AND(M15="En ejecución",L15<>"",L15<TODAY()),"Dice en ejecución pero su terminación ya pasó; ","")&IF(M15="En ejecución","En ejecución: no acredita experiencia; ","")&IF(AND(M15<>"En ejecución",L15<>"",X15<>"",Y15=""),"El año no está en la hoja SMMLV; ","")&IF(AND(B15<>"",COUNTIFS($B$2:$B$601,B15,$C$2:$C$601,C15)>1),"Posible duplicado (mismo número y entidad); ","")&IF(COUNTIF(PARTICIPACIONES!$A$2:$A$601,A15)=0,"Sin participaciones; ","")&IF(SUMIFS(PARTICIPACIONES!$E$2:$E$601,PARTICIPACIONES!$A$2:$A$601,A15)>1.0001,"Las participaciones suman más de 100 %; ",""))
W16: =IF(AND(K16<>"",L16<>""),ROUND((L16-K16)/30.4375,1),"") | X16: =IF(OR(A16="",M16="En ejecución",L16=""),"",YEAR(L16)) | Y16: =IF(X16="","",IFERROR(VLOOKUP(X16,SMMLV!$A$2:$B$38,2,FALSE),"")) | Z16: =IF(OR(Y16="",P16=""),"",ROUND(P16/Y16,2)) | AA16: =IF(Z16="","",ROUND(Z16*SMMLV!$E$4,0)) | AB16: =IF(AND(M16="En ejecución",P16<>"",Q16<>""),MAX(P16-Q16,0),"") | AC16: =IF(A16="","",IF(B16="","Falta número de contrato; ","")&IF(C16="","Falta entidad; ","")&IF(E16="","Falta objeto; ","")&IF(F16="","Falta especialidad; ","")&IF(K16="","Falta fecha de inicio (recomendada); ","")&IF(AND(M16<>"En ejecución",L16=""),"Falta fecha de terminación; ","")&IF(AND(K16<>"",L16<>"",L16<K16),"Terminación anterior al inicio; ","")&IF(M16="","Falta estado; ","")&IF(OR(P16="",P16<=0),"Falta valor del contrato; ","")&IF(AND(M16="En ejecución",Q16=""),"En ejecución sin valor ejecutado; ","")&IF(AND(M16="En ejecución",L16<>"",L16<TODAY()),"Dice en ejecución pero su terminación ya pasó; ","")&IF(M16="En ejecución","En ejecución: no acredita experiencia; ","")&IF(AND(M16<>"En ejecución",L16<>"",X16<>"",Y16=""),"El año no está en la hoja SMMLV; ","")&IF(AND(B16<>"",COUNTIFS($B$2:$B$601,B16,$C$2:$C$601,C16)>1),"Posible duplicado (mismo número y entidad); ","")&IF(COUNTIF(PARTICIPACIONES!$A$2:$A$601,A16)=0,"Sin participaciones; ","")&IF(SUMIFS(PARTICIPACIONES!$E$2:$E$601,PARTICIPACIONES!$A$2:$A$601,A16)>1.0001,"Las participaciones suman más de 100 %; ",""))
... W601: =IF(AND(K601<>"",L601<>""),ROUND((L601-K601)/30.4375,1),"") | X601: =IF(OR(A601="",M601="En ejecución",L601=""),"",YEAR(L601)) | Y601: =IF(X601="","",IFERROR(VLOOKUP(X601,SMMLV!$A$2:$B$38,2,FALSE),"")) | Z601: =IF(OR(Y601="",P601=""),"",ROUND(P601/Y601,2)) | AA601: =IF(Z601="","",ROUND(Z601*SMMLV!$E$4,0)) | AB601: =IF(AND(M601="En ejecución",P601<>"",Q601<>""),MAX(P601-Q601,0),"") | AC601: =IF(A601="","",IF(B601="","Falta número de contrato; ","")&IF(C601="","Falta entidad; ","")&IF(E601="","Falta objeto; ","")&IF(F601="","Falta especialidad; ","")&IF(K601="","Falta fecha de inicio (recomendada); ","")&IF(AND(M601<>"En ejecución",L601=""),"Falta fecha de terminación; ","")&IF(AND(K601<>"",L601<>"",L601<K601),"Terminación anterior al inicio; ","")&IF(M601="","Falta estado; ","")&IF(OR(P601="",P601<=0),"Falta valor del contrato; ","")&IF(AND(M601="En ejecución",Q601=""),"En ejecución sin valor ejecutado; ","")&IF(AND(M601="En ejecución",L601<>"",L601<TODAY()),"Dice en ejecución pero su terminación ya pasó; ","")&IF(M601="En ejecución","En ejecución: no acredita experiencia; ","")&IF(AND(M601<>"En ejecución",L601<>"",X601<>"",Y601=""),"El año no está en la hoja SMMLV; ","")&IF(AND(B601<>"",COUNTIFS($B$2:$B$601,B601,$C$2:$C$601,C601)>1),"Posible duplicado (mismo número y entidad); ","")&IF(COUNTIF(PARTICIPACIONES!$A$2:$A$601,A601)=0,"Sin participaciones; ","")&IF(SUMIFS(PARTICIPACIONES!$E$2:$E$601,PARTICIPACIONES!$A$2:$A$601,A601)>1.0001,"Las participaciones suman más de 100 %; ",""))

Sheet PARTICIPACIONES
A1: ID_CONTRATO | B1: ID_SUJETO | C1: FORMA_EJECUCION | D1: NOMBRE_FIGURA | E1: PORCENTAJE | F1: ROL_EN_FIGURA | G1: CARGO_PROFESIONAL | H1: CERTIFICACION | I1: EN_RUP | J1: SOPORTE_PARTICIPACION | K1: VALOR_PARTICIPADO | L1: SMMLV_PARTICIPADOS | M1: VALOR_ACTUALIZADO_PARTICIPADO | N1: SUMA_PORCENTAJES_CONTRATO | O1: ESPECIALIDAD_CONTRATO | P1: ESTADO_CONTRATO | Q1: ALERTAS | R1: EMPRESA_A_LA_QUE_CUENTA
A2: C-0001 | B2: S-001 | C2: Unión temporal | D2: Unión Temporal Ejemplo | E2: 0.9 | F2: Líder | H2: Sí | I2: Sí | K2: =IF(OR($A2="",$E2=""),"",IFERROR(E2*INDEX(CONTRATOS!$P$2:$P$601,MATCH($A2,CONTRATOS!$A$2:$A$601,0)),"")) | L2: =IF(OR($A2="",$E2=""),"",IFERROR(E2*INDEX(CONTRATOS!$Z$2:$Z$601,MATCH($A2,CONTRATOS!$A$2:$A$601,0)),"")) | M2: =IF(OR($A2="",$E2=""),"",IFERROR(E2*INDEX(CONTRATOS!$AA$2:$AA$601,MATCH($A2,CONTRATOS!$A$2:$A$601,0)),"")) | N2: =IF($A2="","",SUMIFS($E$2:$E$601,$A$2:$A$601,$A2)) | O2: =IF($A2="","",IFERROR(INDEX(CONTRATOS!$F$2:$F$601,MATCH($A2,CONTRATOS!$A$2:$A$601,0)),"")) | P2: =IF($A2="","",IFERROR(INDEX(CONTRATOS!$M$2:$M$601,MATCH($A2,CONTRATOS!$A$2:$A$601,0)),"")) | Q2: =IF($A2="","",IF(COUNTIF(CONTRATOS!$A$2:$A$601,$A2)=0,"El contrato no existe en CONTRATOS; ","")&IF($B2="","Falta sujeto; ",IF(COUNTIF(SUJETOS!$A$2:$A$601,$B2)=0,"El sujeto no existe en SUJETOS; ",""))&IF($E2="","Falta porcentaje; ","")&IF(N2>1.0001,"Los porcentajes del contrato suman más de 100 %; ","")&IF(AND($C2="Individual",$E2<>"",$E2<>1),"Individual debe ser 100 %; ","")&IF(AND($C2<>"Individual",$C2<>"",$E2=1),"Consorcio o UT con 100 %: revise; ","")&IF(COUNTIFS($A$2:$A$601,$A2,$B$2:$B$601,$B2)>1,"Participación repetida; ","")&IF(AND(IFERROR(INDEX(SUJETOS!$B$2:$B$601,MATCH($B2,SUJETOS!$A$2:$A$601,0)),"")="Persona natural",$G2=""),"Persona natural sin cargo; ","")) | R2: =IF($A2="","",IFERROR(IF(LEN(INDEX(SUJETOS!$F$2:$F$601,MATCH($B2,SUJETOS!$A$2:$A$601,0)))>0,INDEX(SUJETOS!$F$2:$F$601,MATCH($B2,SUJETOS!$A$2:$A$601,0)),$B2),$B2))
A3: C-0001 | B3: S-002 | C3: Unión temporal | D3: Unión Temporal Ejemplo | E3: 0.1 | F3: Integrante | G3: Contratista | H3: Sí | I3: Sí | K3: =IF(OR($A3="",$E3=""),"",IFERROR(E3*INDEX(CONTRATOS!$P$2:$P$601,MATCH($A3,CONTRATOS!$A$2:$A$601,0)),"")) | L3: =IF(OR($A3="",$E3=""),"",IFERROR(E3*INDEX(CONTRATOS!$Z$2:$Z$601,MATCH($A3,CONTRATOS!$A$2:$A$601,0)),"")) | M3: =IF(OR($A3="",$E3=""),"",IFERROR(E3*INDEX(CONTRATOS!$AA$2:$AA$601,MATCH($A3,CONTRATOS!$A$2:$A$601,0)),"")) | N3: =IF($A3="","",SUMIFS($E$2:$E$601,$A$2:$A$601,$A3)) | O3: =IF($A3="","",IFERROR(INDEX(CONTRATOS!$F$2:$F$601,MATCH($A3,CONTRATOS!$A$2:$A$601,0)),"")) | P3: =IF($A3="","",IFERROR(INDEX(CONTRATOS!$M$2:$M$601,MATCH($A3,CONTRATOS!$A$2:$A$601,0)),"")) | Q3: =IF($A3="","",IF(COUNTIF(CONTRATOS!$A$2:$A$601,$A3)=0,"El contrato no existe en CONTRATOS; ","")&IF($B3="","Falta sujeto; ",IF(COUNTIF(SUJETOS!$A$2:$A$601,$B3)=0,"El sujeto no existe en SUJETOS; ",""))&IF($E3="","Falta porcentaje; ","")&IF(N3>1.0001,"Los porcentajes del contrato suman más de 100 %; ","")&IF(AND($C3="Individual",$E3<>"",$E3<>1),"Individual debe ser 100 %; ","")&IF(AND($C3<>"Individual",$C3<>"",$E3=1),"Consorcio o UT con 100 %: revise; ","")&IF(COUNTIFS($A$2:$A$601,$A3,$B$2:$B$601,$B3)>1,"Participación repetida; ","")&IF(AND(IFERROR(INDEX(SUJETOS!$B$2:$B$601,MATCH($B3,SUJETOS!$A$2:$A$601,0)),"")="Persona natural",$G3=""),"Persona natural sin cargo; ","")) | R3: =IF($A3="","",IFERROR(IF(LEN(INDEX(SUJETOS!$F$2:$F$601,MATCH($B3,SUJETOS!$A$2:$A$601,0)))>0,INDEX(SUJETOS!$F$2:$F$601,MATCH($B3,SUJETOS!$A$2:$A$601,0)),$B3),$B3))
A4: C-0002 | B4: S-001 | C4: Individual | E4: 1 | H4: Sí | I4: Sí | K4: =IF(OR($A4="",$E4=""),"",IFERROR(E4*INDEX(CONTRATOS!$P$2:$P$601,MATCH($A4,CONTRATOS!$A$2:$A$601,0)),"")) | L4: =IF(OR($A4="",$E4=""),"",IFERROR(E4*INDEX(CONTRATOS!$Z$2:$Z$601,MATCH($A4,CONTRATOS!$A$2:$A$601,0)),"")) | M4: =IF(OR($A4="",$E4=""),"",IFERROR(E4*INDEX(CONTRATOS!$AA$2:$AA$601,MATCH($A4,CONTRATOS!$A$2:$A$601,0)),"")) | N4: =IF($A4="","",SUMIFS($E$2:$E$601,$A$2:$A$601,$A4)) | O4: =IF($A4="","",IFERROR(INDEX(CONTRATOS!$F$2:$F$601,MATCH($A4,CONTRATOS!$A$2:$A$601,0)),"")) | P4: =IF($A4="","",IFERROR(INDEX(CONTRATOS!$M$2:$M$601,MATCH($A4,CONTRATOS!$A$2:$A$601,0)),"")) | Q4: =IF($A4="","",IF(COUNTIF(CONTRATOS!$A$2:$A$601,$A4)=0,"El contrato no existe en CONTRATOS; ","")&IF($B4="","Falta sujeto; ",IF(COUNTIF(SUJETOS!$A$2:$A$601,$B4)=0,"El sujeto no existe en SUJETOS; ",""))&IF($E4="","Falta porcentaje; ","")&IF(N4>1.0001,"Los porcentajes del contrato suman más de 100 %; ","")&IF(AND($C4="Individual",$E4<>"",$E4<>1),"Individual debe ser 100 %; ","")&IF(AND($C4<>"Individual",$C4<>"",$E4=1),"Consorcio o UT con 100 %: revise; ","")&IF(COUNTIFS($A$2:$A$601,$A4,$B$2:$B$601,$B4)>1,"Participación repetida; ","")&IF(AND(IFERROR(INDEX(SUJETOS!$B$2:$B$601,MATCH($B4,SUJETOS!$A$2:$A$601,0)),"")="Persona natural",$G4=""),"Persona natural sin cargo; ","")) | R4: =IF($A4="","",IFERROR(IF(LEN(INDEX(SUJETOS!$F$2:$F$601,MATCH($B4,SUJETOS!$A$2:$A$601,0)))>0,INDEX(SUJETOS!$F$2:$F$601,MATCH($B4,SUJETOS!$A$2:$A$601,0)),$B4),$B4))
A5: C-0003 | B5: S-003 | C5: Individual | E5: 1 | H5: Pendiente | I5: Sí | K5: =IF(OR($A5="",$E5=""),"",IFERROR(E5*INDEX(CONTRATOS!$P$2:$P$601,MATCH($A5,CONTRATOS!$A$2:$A$601,0)),"")) | L5: =IF(OR($A5="",$E5=""),"",IFERROR(E5*INDEX(CONTRATOS!$Z$2:$Z$601,MATCH($A5,CONTRATOS!$A$2:$A$601,0)),"")) | M5: =IF(OR($A5="",$E5=""),"",IFERROR(E5*INDEX(CONTRATOS!$AA$2:$AA$601,MATCH($A5,CONTRATOS!$A$2:$A$601,0)),"")) | N5: =IF($A5="","",SUMIFS($E$2:$E$601,$A$2:$A$601,$A5)) | O5: =IF($A5="","",IFERROR(INDEX(CONTRATOS!$F$2:$F$601,MATCH($A5,CONTRATOS!$A$2:$A$601,0)),"")) | P5: =IF($A5="","",IFERROR(INDEX(CONTRATOS!$M$2:$M$601,MATCH($A5,CONTRATOS!$A$2:$A$601,0)),"")) | Q5: =IF($A5="","",IF(COUNTIF(CONTRATOS!$A$2:$A$601,$A5)=0,"El contrato no existe en CONTRATOS; ","")&IF($B5="","Falta sujeto; ",IF(COUNTIF(SUJETOS!$A$2:$A$601,$B5)=0,"El sujeto no existe en SUJETOS; ",""))&IF($E5="","Falta porcentaje; ","")&IF(N5>1.0001,"Los porcentajes del contrato suman más de 100 %; ","")&IF(AND($C5="Individual",$E5<>"",$E5<>1),"Individual debe ser 100 %; ","")&IF(AND($C5<>"Individual",$C5<>"",$E5=1),"Consorcio o UT con 100 %: revise; ","")&IF(COUNTIFS($A$2:$A$601,$A5,$B$2:$B$601,$B5)>1,"Participación repetida; ","")&IF(AND(IFERROR(INDEX(SUJETOS!$B$2:$B$601,MATCH($B5,SUJETOS!$A$2:$A$601,0)),"")="Persona natural",$G5=""),"Persona natural sin cargo; ","")) | R5: =IF($A5="","",IFERROR(IF(LEN(INDEX(SUJETOS!$F$2:$F$601,MATCH($B5,SUJETOS!$A$2:$A$601,0)))>0,INDEX(SUJETOS!$F$2:$F$601,MATCH($B5,SUJETOS!$A$2:$A$601,0)),$B5),$B5))
K6: =IF(OR($A6="",$E6=""),"",IFERROR(E6*INDEX(CONTRATOS!$P$2:$P$601,MATCH($A6,CONTRATOS!$A$2:$A$601,0)),"")) | L6: =IF(OR($A6="",$E6=""),"",IFERROR(E6*INDEX(CONTRATOS!$Z$2:$Z$601,MATCH($A6,CONTRATOS!$A$2:$A$601,0)),"")) | M6: =IF(OR($A6="",$E6=""),"",IFERROR(E6*INDEX(CONTRATOS!$AA$2:$AA$601,MATCH($A6,CONTRATOS!$A$2:$A$601,0)),"")) | N6: =IF($A6="","",SUMIFS($E$2:$E$601,$A$2:$A$601,$A6)) | O6: =IF($A6="","",IFERROR(INDEX(CONTRATOS!$F$2:$F$601,MATCH($A6,CONTRATOS!$A$2:$A$601,0)),"")) | P6: =IF($A6="","",IFERROR(INDEX(CONTRATOS!$M$2:$M$601,MATCH($A6,CONTRATOS!$A$2:$A$601,0)),"")) | Q6: =IF($A6="","",IF(COUNTIF(CONTRATOS!$A$2:$A$601,$A6)=0,"El contrato no existe en CONTRATOS; ","")&IF($B6="","Falta sujeto; ",IF(COUNTIF(SUJETOS!$A$2:$A$601,$B6)=0,"El sujeto no existe en SUJETOS; ",""))&IF($E6="","Falta porcentaje; ","")&IF(N6>1.0001,"Los porcentajes del contrato suman más de 100 %; ","")&IF(AND($C6="Individual",$E6<>"",$E6<>1),"Individual debe ser 100 %; ","")&IF(AND($C6<>"Individual",$C6<>"",$E6=1),"Consorcio o UT con 100 %: revise; ","")&IF(COUNTIFS($A$2:$A$601,$A6,$B$2:$B$601,$B6)>1,"Participación repetida; ","")&IF(AND(IFERROR(INDEX(SUJETOS!$B$2:$B$601,MATCH($B6,SUJETOS!$A$2:$A$601,0)),"")="Persona natural",$G6=""),"Persona natural sin cargo; ","")) | R6: =IF($A6="","",IFERROR(IF(LEN(INDEX(SUJETOS!$F$2:$F$601,MATCH($B6,SUJETOS!$A$2:$A$601,0)))>0,INDEX(SUJETOS!$F$2:$F$601,MATCH($B6,SUJETOS!$A$2:$A$601,0)),$B6),$B6))
K7: =IF(OR($A7="",$E7=""),"",IFERROR(E7*INDEX(CONTRATOS!$P$2:$P$601,MATCH($A7,CONTRATOS!$A$2:$A$601,0)),"")) | L7: =IF(OR($A7="",$E7=""),"",IFERROR(E7*INDEX(CONTRATOS!$Z$2:$Z$601,MATCH($A7,CONTRATOS!$A$2:$A$601,0)),"")) | M7: =IF(OR($A7="",$E7=""),"",IFERROR(E7*INDEX(CONTRATOS!$AA$2:$AA$601,MATCH($A7,CONTRATOS!$A$2:$A$601,0)),"")) | N7: =IF($A7="","",SUMIFS($E$2:$E$601,$A$2:$A$601,$A7)) | O7: =IF($A7="","",IFERROR(INDEX(CONTRATOS!$F$2:$F$601,MATCH($A7,CONTRATOS!$A$2:$A$601,0)),"")) | P7: =IF($A7="","",IFERROR(INDEX(CONTRATOS!$M$2:$M$601,MATCH($A7,CONTRATOS!$A$2:$A$601,0)),"")) | Q7: =IF($A7="","",IF(COUNTIF(CONTRATOS!$A$2:$A$601,$A7)=0,"El contrato no existe en CONTRATOS; ","")&IF($B7="","Falta sujeto; ",IF(COUNTIF(SUJETOS!$A$2:$A$601,$B7)=0,"El sujeto no existe en SUJETOS; ",""))&IF($E7="","Falta porcentaje; ","")&IF(N7>1.0001,"Los porcentajes del contrato suman más de 100 %; ","")&IF(AND($C7="Individual",$E7<>"",$E7<>1),"Individual debe ser 100 %; ","")&IF(AND($C7<>"Individual",$C7<>"",$E7=1),"Consorcio o UT con 100 %: revise; ","")&IF(COUNTIFS($A$2:$A$601,$A7,$B$2:$B$601,$B7)>1,"Participación repetida; ","")&IF(AND(IFERROR(INDEX(SUJETOS!$B$2:$B$601,MATCH($B7,SUJETOS!$A$2:$A$601,0)),"")="Persona natural",$G7=""),"Persona natural sin cargo; ","")) | R7: =IF($A7="","",IFERROR(IF(LEN(INDEX(SUJETOS!$F$2:$F$601,MATCH($B7,SUJETOS!$A$2:$A$601,0)))>0,INDEX(SUJETOS!$F$2:$F$601,MATCH($B7,SUJETOS!$A$2:$A$601,0)),$B7),$B7))
K8: =IF(OR($A8="",$E8=""),"",IFERROR(E8*INDEX(CONTRATOS!$P$2:$P$601,MATCH($A8,CONTRATOS!$A$2:$A$601,0)),"")) | L8: =IF(OR($A8="",$E8=""),"",IFERROR(E8*INDEX(CONTRATOS!$Z$2:$Z$601,MATCH($A8,CONTRATOS!$A$2:$A$601,0)),"")) | M8: =IF(OR($A8="",$E8=""),"",IFERROR(E8*INDEX(CONTRATOS!$AA$2:$AA$601,MATCH($A8,CONTRATOS!$A$2:$A$601,0)),"")) | N8: =IF($A8="","",SUMIFS($E$2:$E$601,$A$2:$A$601,$A8)) | O8: =IF($A8="","",IFERROR(INDEX(CONTRATOS!$F$2:$F$601,MATCH($A8,CONTRATOS!$A$2:$A$601,0)),"")) | P8: =IF($A8="","",IFERROR(INDEX(CONTRATOS!$M$2:$M$601,MATCH($A8,CONTRATOS!$A$2:$A$601,0)),"")) | Q8: =IF($A8="","",IF(COUNTIF(CONTRATOS!$A$2:$A$601,$A8)=0,"El contrato no existe en CONTRATOS; ","")&IF($B8="","Falta sujeto; ",IF(COUNTIF(SUJETOS!$A$2:$A$601,$B8)=0,"El sujeto no existe en SUJETOS; ",""))&IF($E8="","Falta porcentaje; ","")&IF(N8>1.0001,"Los porcentajes del contrato suman más de 100 %; ","")&IF(AND($C8="Individual",$E8<>"",$E8<>1),"Individual debe ser 100 %; ","")&IF(AND($C8<>"Individual",$C8<>"",$E8=1),"Consorcio o UT con 100 %: revise; ","")&IF(COUNTIFS($A$2:$A$601,$A8,$B$2:$B$601,$B8)>1,"Participación repetida; ","")&IF(AND(IFERROR(INDEX(SUJETOS!$B$2:$B$601,MATCH($B8,SUJETOS!$A$2:$A$601,0)),"")="Persona natural",$G8=""),"Persona natural sin cargo; ","")) | R8: =IF($A8="","",IFERROR(IF(LEN(INDEX(SUJETOS!$F$2:$F$601,MATCH($B8,SUJETOS!$A$2:$A$601,0)))>0,INDEX(SUJETOS!$F$2:$F$601,MATCH($B8,SUJETOS!$A$2:$A$601,0)),$B8),$B8))
K9: =IF(OR($A9="",$E9=""),"",IFERROR(E9*INDEX(CONTRATOS!$P$2:$P$601,MATCH($A9,CONTRATOS!$A$2:$A$601,0)),"")) | L9: =IF(OR($A9="",$E9=""),"",IFERROR(E9*INDEX(CONTRATOS!$Z$2:$Z$601,MATCH($A9,CONTRATOS!$A$2:$A$601,0)),"")) | M9: =IF(OR($A9="",$E9=""),"",IFERROR(E9*INDEX(CONTRATOS!$AA$2:$AA$601,MATCH($A9,CONTRATOS!$A$2:$A$601,0)),"")) | N9: =IF($A9="","",SUMIFS($E$2:$E$601,$A$2:$A$601,$A9)) | O9: =IF($A9="","",IFERROR(INDEX(CONTRATOS!$F$2:$F$601,MATCH($A9,CONTRATOS!$A$2:$A$601,0)),"")) | P9: =IF($A9="","",IFERROR(INDEX(CONTRATOS!$M$2:$M$601,MATCH($A9,CONTRATOS!$A$2:$A$601,0)),"")) | Q9: =IF($A9="","",IF(COUNTIF(CONTRATOS!$A$2:$A$601,$A9)=0,"El contrato no existe en CONTRATOS; ","")&IF($B9="","Falta sujeto; ",IF(COUNTIF(SUJETOS!$A$2:$A$601,$B9)=0,"El sujeto no existe en SUJETOS; ",""))&IF($E9="","Falta porcentaje; ","")&IF(N9>1.0001,"Los porcentajes del contrato suman más de 100 %; ","")&IF(AND($C9="Individual",$E9<>"",$E9<>1),"Individual debe ser 100 %; ","")&IF(AND($C9<>"Individual",$C9<>"",$E9=1),"Consorcio o UT con 100 %: revise; ","")&IF(COUNTIFS($A$2:$A$601,$A9,$B$2:$B$601,$B9)>1,"Participación repetida; ","")&IF(AND(IFERROR(INDEX(SUJETOS!$B$2:$B$601,MATCH($B9,SUJETOS!$A$2:$A$601,0)),"")="Persona natural",$G9=""),"Persona natural sin cargo; ","")) | R9: =IF($A9="","",IFERROR(IF(LEN(INDEX(SUJETOS!$F$2:$F$601,MATCH($B9,SUJETOS!$A$2:$A$601,0)))>0,INDEX(SUJETOS!$F$2:$F$601,MATCH($B9,SUJETOS!$A$2:$A$601,0)),$B9),$B9))
K10: =IF(OR($A10="",$E10=""),"",IFERROR(E10*INDEX(CONTRATOS!$P$2:$P$601,MATCH($A10,CONTRATOS!$A$2:$A$601,0)),"")) | L10: =IF(OR($A10="",$E10=""),"",IFERROR(E10*INDEX(CONTRATOS!$Z$2:$Z$601,MATCH($A10,CONTRATOS!$A$2:$A$601,0)),"")) | M10: =IF(OR($A10="",$E10=""),"",IFERROR(E10*INDEX(CONTRATOS!$AA$2:$AA$601,MATCH($A10,CONTRATOS!$A$2:$A$601,0)),"")) | N10: =IF($A10="","",SUMIFS($E$2:$E$601,$A$2:$A$601,$A10)) | O10: =IF($A10="","",IFERROR(INDEX(CONTRATOS!$F$2:$F$601,MATCH($A10,CONTRATOS!$A$2:$A$601,0)),"")) | P10: =IF($A10="","",IFERROR(INDEX(CONTRATOS!$M$2:$M$601,MATCH($A10,CONTRATOS!$A$2:$A$601,0)),"")) | Q10: =IF($A10="","",IF(COUNTIF(CONTRATOS!$A$2:$A$601,$A10)=0,"El contrato no existe en CONTRATOS; ","")&IF($B10="","Falta sujeto; ",IF(COUNTIF(SUJETOS!$A$2:$A$601,$B10)=0,"El sujeto no existe en SUJETOS; ",""))&IF($E10="","Falta porcentaje; ","")&IF(N10>1.0001,"Los porcentajes del contrato suman más de 100 %; ","")&IF(AND($C10="Individual",$E10<>"",$E10<>1),"Individual debe ser 100 %; ","")&IF(AND($C10<>"Individual",$C10<>"",$E10=1),"Consorcio o UT con 100 %: revise; ","")&IF(COUNTIFS($A$2:$A$601,$A10,$B$2:$B$601,$B10)>1,"Participación repetida; ","")&IF(AND(IFERROR(INDEX(SUJETOS!$B$2:$B$601,MATCH($B10,SUJETOS!$A$2:$A$601,0)),"")="Persona natural",$G10=""),"Persona natural sin cargo; ","")) | R10: =IF($A10="","",IFERROR(IF(LEN(INDEX(SUJETOS!$F$2:$F$601,MATCH($B10,SUJETOS!$A$2:$A$601,0)))>0,INDEX(SUJETOS!$F$2:$F$601,MATCH($B10,SUJETOS!$A$2:$A$601,0)),$B10),$B10))
K11: =IF(OR($A11="",$E11=""),"",IFERROR(E11*INDEX(CONTRATOS!$P$2:$P$601,MATCH($A11,CONTRATOS!$A$2:$A$601,0)),"")) | L11: =IF(OR($A11="",$E11=""),"",IFERROR(E11*INDEX(CONTRATOS!$Z$2:$Z$601,MATCH($A11,CONTRATOS!$A$2:$A$601,0)),"")) | M11: =IF(OR($A11="",$E11=""),"",IFERROR(E11*INDEX(CONTRATOS!$AA$2:$AA$601,MATCH($A11,CONTRATOS!$A$2:$A$601,0)),"")) | N11: =IF($A11="","",SUMIFS($E$2:$E$601,$A$2:$A$601,$A11)) | O11: =IF($A11="","",IFERROR(INDEX(CONTRATOS!$F$2:$F$601,MATCH($A11,CONTRATOS!$A$2:$A$601,0)),"")) | P11: =IF($A11="","",IFERROR(INDEX(CONTRATOS!$M$2:$M$601,MATCH($A11,CONTRATOS!$A$2:$A$601,0)),"")) | Q11: =IF($A11="","",IF(COUNTIF(CONTRATOS!$A$2:$A$601,$A11)=0,"El contrato no existe en CONTRATOS; ","")&IF($B11="","Falta sujeto; ",IF(COUNTIF(SUJETOS!$A$2:$A$601,$B11)=0,"El sujeto no existe en SUJETOS; ",""))&IF($E11="","Falta porcentaje; ","")&IF(N11>1.0001,"Los porcentajes del contrato suman más de 100 %; ","")&IF(AND($C11="Individual",$E11<>"",$E11<>1),"Individual debe ser 100 %; ","")&IF(AND($C11<>"Individual",$C11<>"",$E11=1),"Consorcio o UT con 100 %: revise; ","")&IF(COUNTIFS($A$2:$A$601,$A11,$B$2:$B$601,$B11)>1,"Participación repetida; ","")&IF(AND(IFERROR(INDEX(SUJETOS!$B$2:$B$601,MATCH($B11,SUJETOS!$A$2:$A$601,0)),"")="Persona natural",$G11=""),"Persona natural sin cargo; ","")) | R11: =IF($A11="","",IFERROR(IF(LEN(INDEX(SUJETOS!$F$2:$F$601,MATCH($B11,SUJETOS!$A$2:$A$601,0)))>0,INDEX(SUJETOS!$F$2:$F$601,MATCH($B11,SUJETOS!$A$2:$A$601,0)),$B11),$B11))
K12: =IF(OR($A12="",$E12=""),"",IFERROR(E12*INDEX(CONTRATOS!$P$2:$P$601,MATCH($A12,CONTRATOS!$A$2:$A$601,0)),"")) | L12: =IF(OR($A12="",$E12=""),"",IFERROR(E12*INDEX(CONTRATOS!$Z$2:$Z$601,MATCH($A12,CONTRATOS!$A$2:$A$601,0)),"")) | M12: =IF(OR($A12="",$E12=""),"",IFERROR(E12*INDEX(CONTRATOS!$AA$2:$AA$601,MATCH($A12,CONTRATOS!$A$2:$A$601,0)),"")) | N12: =IF($A12="","",SUMIFS($E$2:$E$601,$A$2:$A$601,$A12)) | O12: =IF($A12="","",IFERROR(INDEX(CONTRATOS!$F$2:$F$601,MATCH($A12,CONTRATOS!$A$2:$A$601,0)),"")) | P12: =IF($A12="","",IFERROR(INDEX(CONTRATOS!$M$2:$M$601,MATCH($A12,CONTRATOS!$A$2:$A$601,0)),"")) | Q12: =IF($A12="","",IF(COUNTIF(CONTRATOS!$A$2:$A$601,$A12)=0,"El contrato no existe en CONTRATOS; ","")&IF($B12="","Falta sujeto; ",IF(COUNTIF(SUJETOS!$A$2:$A$601,$B12)=0,"El sujeto no existe en SUJETOS; ",""))&IF($E12="","Falta porcentaje; ","")&IF(N12>1.0001,"Los porcentajes del contrato suman más de 100 %; ","")&IF(AND($C12="Individual",$E12<>"",$E12<>1),"Individual debe ser 100 %; ","")&IF(AND($C12<>"Individual",$C12<>"",$E12=1),"Consorcio o UT con 100 %: revise; ","")&IF(COUNTIFS($A$2:$A$601,$A12,$B$2:$B$601,$B12)>1,"Participación repetida; ","")&IF(AND(IFERROR(INDEX(SUJETOS!$B$2:$B$601,MATCH($B12,SUJETOS!$A$2:$A$601,0)),"")="Persona natural",$G12=""),"Persona natural sin cargo; ","")) | R12: =IF($A12="","",IFERROR(IF(LEN(INDEX(SUJETOS!$F$2:$F$601,MATCH($B12,SUJETOS!$A$2:$A$601,0)))>0,INDEX(SUJETOS!$F$2:$F$601,MATCH($B12,SUJETOS!$A$2:$A$601,0)),$B12),$B12))
K13: =IF(OR($A13="",$E13=""),"",IFERROR(E13*INDEX(CONTRATOS!$P$2:$P$601,MATCH($A13,CONTRATOS!$A$2:$A$601,0)),"")) | L13: =IF(OR($A13="",$E13=""),"",IFERROR(E13*INDEX(CONTRATOS!$Z$2:$Z$601,MATCH($A13,CONTRATOS!$A$2:$A$601,0)),"")) | M13: =IF(OR($A13="",$E13=""),"",IFERROR(E13*INDEX(CONTRATOS!$AA$2:$AA$601,MATCH($A13,CONTRATOS!$A$2:$A$601,0)),"")) | N13: =IF($A13="","",SUMIFS($E$2:$E$601,$A$2:$A$601,$A13)) | O13: =IF($A13="","",IFERROR(INDEX(CONTRATOS!$F$2:$F$601,MATCH($A13,CONTRATOS!$A$2:$A$601,0)),"")) | P13: =IF($A13="","",IFERROR(INDEX(CONTRATOS!$M$2:$M$601,MATCH($A13,CONTRATOS!$A$2:$A$601,0)),"")) | Q13: =IF($A13="","",IF(COUNTIF(CONTRATOS!$A$2:$A$601,$A13)=0,"El contrato no existe en CONTRATOS; ","")&IF($B13="","Falta sujeto; ",IF(COUNTIF(SUJETOS!$A$2:$A$601,$B13)=0,"El sujeto no existe en SUJETOS; ",""))&IF($E13="","Falta porcentaje; ","")&IF(N13>1.0001,"Los porcentajes del contrato suman más de 100 %; ","")&IF(AND($C13="Individual",$E13<>"",$E13<>1),"Individual debe ser 100 %; ","")&IF(AND($C13<>"Individual",$C13<>"",$E13=1),"Consorcio o UT con 100 %: revise; ","")&IF(COUNTIFS($A$2:$A$601,$A13,$B$2:$B$601,$B13)>1,"Participación repetida; ","")&IF(AND(IFERROR(INDEX(SUJETOS!$B$2:$B$601,MATCH($B13,SUJETOS!$A$2:$A$601,0)),"")="Persona natural",$G13=""),"Persona natural sin cargo; ","")) | R13: =IF($A13="","",IFERROR(IF(LEN(INDEX(SUJETOS!$F$2:$F$601,MATCH($B13,SUJETOS!$A$2:$A$601,0)))>0,INDEX(SUJETOS!$F$2:$F$601,MATCH($B13,SUJETOS!$A$2:$A$601,0)),$B13),$B13))
K14: =IF(OR($A14="",$E14=""),"",IFERROR(E14*INDEX(CONTRATOS!$P$2:$P$601,MATCH($A14,CONTRATOS!$A$2:$A$601,0)),"")) | L14: =IF(OR($A14="",$E14=""),"",IFERROR(E14*INDEX(CONTRATOS!$Z$2:$Z$601,MATCH($A14,CONTRATOS!$A$2:$A$601,0)),"")) | M14: =IF(OR($A14="",$E14=""),"",IFERROR(E14*INDEX(CONTRATOS!$AA$2:$AA$601,MATCH($A14,CONTRATOS!$A$2:$A$601,0)),"")) | N14: =IF($A14="","",SUMIFS($E$2:$E$601,$A$2:$A$601,$A14)) | O14: =IF($A14="","",IFERROR(INDEX(CONTRATOS!$F$2:$F$601,MATCH($A14,CONTRATOS!$A$2:$A$601,0)),"")) | P14: =IF($A14="","",IFERROR(INDEX(CONTRATOS!$M$2:$M$601,MATCH($A14,CONTRATOS!$A$2:$A$601,0)),"")) | Q14: =IF($A14="","",IF(COUNTIF(CONTRATOS!$A$2:$A$601,$A14)=0,"El contrato no existe en CONTRATOS; ","")&IF($B14="","Falta sujeto; ",IF(COUNTIF(SUJETOS!$A$2:$A$601,$B14)=0,"El sujeto no existe en SUJETOS; ",""))&IF($E14="","Falta porcentaje; ","")&IF(N14>1.0001,"Los porcentajes del contrato suman más de 100 %; ","")&IF(AND($C14="Individual",$E14<>"",$E14<>1),"Individual debe ser 100 %; ","")&IF(AND($C14<>"Individual",$C14<>"",$E14=1),"Consorcio o UT con 100 %: revise; ","")&IF(COUNTIFS($A$2:$A$601,$A14,$B$2:$B$601,$B14)>1,"Participación repetida; ","")&IF(AND(IFERROR(INDEX(SUJETOS!$B$2:$B$601,MATCH($B14,SUJETOS!$A$2:$A$601,0)),"")="Persona natural",$G14=""),"Persona natural sin cargo; ","")) | R14: =IF($A14="","",IFERROR(IF(LEN(INDEX(SUJETOS!$F$2:$F$601,MATCH($B14,SUJETOS!$A$2:$A$601,0)))>0,INDEX(SUJETOS!$F$2:$F$601,MATCH($B14,SUJETOS!$A$2:$A$601,0)),$B14),$B14))
K15: =IF(OR($A15="",$E15=""),"",IFERROR(E15*INDEX(CONTRATOS!$P$2:$P$601,MATCH($A15,CONTRATOS!$A$2:$A$601,0)),"")) | L15: =IF(OR($A15="",$E15=""),"",IFERROR(E15*INDEX(CONTRATOS!$Z$2:$Z$601,MATCH($A15,CONTRATOS!$A$2:$A$601,0)),"")) | M15: =IF(OR($A15="",$E15=""),"",IFERROR(E15*INDEX(CONTRATOS!$AA$2:$AA$601,MATCH($A15,CONTRATOS!$A$2:$A$601,0)),"")) | N15: =IF($A15="","",SUMIFS($E$2:$E$601,$A$2:$A$601,$A15)) | O15: =IF($A15="","",IFERROR(INDEX(CONTRATOS!$F$2:$F$601,MATCH($A15,CONTRATOS!$A$2:$A$601,0)),"")) | P15: =IF($A15="","",IFERROR(INDEX(CONTRATOS!$M$2:$M$601,MATCH($A15,CONTRATOS!$A$2:$A$601,0)),"")) | Q15: =IF($A15="","",IF(COUNTIF(CONTRATOS!$A$2:$A$601,$A15)=0,"El contrato no existe en CONTRATOS; ","")&IF($B15="","Falta sujeto; ",IF(COUNTIF(SUJETOS!$A$2:$A$601,$B15)=0,"El sujeto no existe en SUJETOS; ",""))&IF($E15="","Falta porcentaje; ","")&IF(N15>1.0001,"Los porcentajes del contrato suman más de 100 %; ","")&IF(AND($C15="Individual",$E15<>"",$E15<>1),"Individual debe ser 100 %; ","")&IF(AND($C15<>"Individual",$C15<>"",$E15=1),"Consorcio o UT con 100 %: revise; ","")&IF(COUNTIFS($A$2:$A$601,$A15,$B$2:$B$601,$B15)>1,"Participación repetida; ","")&IF(AND(IFERROR(INDEX(SUJETOS!$B$2:$B$601,MATCH($B15,SUJETOS!$A$2:$A$601,0)),"")="Persona natural",$G15=""),"Persona natural sin cargo; ","")) | R15: =IF($A15="","",IFERROR(IF(LEN(INDEX(SUJETOS!$F$2:$F$601,MATCH($B15,SUJETOS!$A$2:$A$601,0)))>0,INDEX(SUJETOS!$F$2:$F$601,MATCH($B15,SUJETOS!$A$2:$A$601,0)),$B15),$B15))
K16: =IF(OR($A16="",$E16=""),"",IFERROR(E16*INDEX(CONTRATOS!$P$2:$P$601,MATCH($A16,CONTRATOS!$A$2:$A$601,0)),"")) | L16: =IF(OR($A16="",$E16=""),"",IFERROR(E16*INDEX(CONTRATOS!$Z$2:$Z$601,MATCH($A16,CONTRATOS!$A$2:$A$601,0)),"")) | M16: =IF(OR($A16="",$E16=""),"",IFERROR(E16*INDEX(CONTRATOS!$AA$2:$AA$601,MATCH($A16,CONTRATOS!$A$2:$A$601,0)),"")) | N16: =IF($A16="","",SUMIFS($E$2:$E$601,$A$2:$A$601,$A16)) | O16: =IF($A16="","",IFERROR(INDEX(CONTRATOS!$F$2:$F$601,MATCH($A16,CONTRATOS!$A$2:$A$601,0)),"")) | P16: =IF($A16="","",IFERROR(INDEX(CONTRATOS!$M$2:$M$601,MATCH($A16,CONTRATOS!$A$2:$A$601,0)),"")) | Q16: =IF($A16="","",IF(COUNTIF(CONTRATOS!$A$2:$A$601,$A16)=0,"El contrato no existe en CONTRATOS; ","")&IF($B16="","Falta sujeto; ",IF(COUNTIF(SUJETOS!$A$2:$A$601,$B16)=0,"El sujeto no existe en SUJETOS; ",""))&IF($E16="","Falta porcentaje; ","")&IF(N16>1.0001,"Los porcentajes del contrato suman más de 100 %; ","")&IF(AND($C16="Individual",$E16<>"",$E16<>1),"Individual debe ser 100 %; ","")&IF(AND($C16<>"Individual",$C16<>"",$E16=1),"Consorcio o UT con 100 %: revise; ","")&IF(COUNTIFS($A$2:$A$601,$A16,$B$2:$B$601,$B16)>1,"Participación repetida; ","")&IF(AND(IFERROR(INDEX(SUJETOS!$B$2:$B$601,MATCH($B16,SUJETOS!$A$2:$A$601,0)),"")="Persona natural",$G16=""),"Persona natural sin cargo; ","")) | R16: =IF($A16="","",IFERROR(IF(LEN(INDEX(SUJETOS!$F$2:$F$601,MATCH($B16,SUJETOS!$A$2:$A$601,0)))>0,INDEX(SUJETOS!$F$2:$F$601,MATCH($B16,SUJETOS!$A$2:$A$601,0)),$B16),$B16))
K17: =IF(OR($A17="",$E17=""),"",IFERROR(E17*INDEX(CONTRATOS!$P$2:$P$601,MATCH($A17,CONTRATOS!$A$2:$A$601,0)),"")) | L17: =IF(OR($A17="",$E17=""),"",IFERROR(E17*INDEX(CONTRATOS!$Z$2:$Z$601,MATCH($A17,CONTRATOS!$A$2:$A$601,0)),"")) | M17: =IF(OR($A17="",$E17=""),"",IFERROR(E17*INDEX(CONTRATOS!$AA$2:$AA$601,MATCH($A17,CONTRATOS!$A$2:$A$601,0)),"")) | N17: =IF($A17="","",SUMIFS($E$2:$E$601,$A$2:$A$601,$A17)) | O17: =IF($A17="","",IFERROR(INDEX(CONTRATOS!$F$2:$F$601,MATCH($A17,CONTRATOS!$A$2:$A$601,0)),"")) | P17: =IF($A17="","",IFERROR(INDEX(CONTRATOS!$M$2:$M$601,MATCH($A17,CONTRATOS!$A$2:$A$601,0)),"")) | Q17: =IF($A17="","",IF(COUNTIF(CONTRATOS!$A$2:$A$601,$A17)=0,"El contrato no existe en CONTRATOS; ","")&IF($B17="","Falta sujeto; ",IF(COUNTIF(SUJETOS!$A$2:$A$601,$B17)=0,"El sujeto no existe en SUJETOS; ",""))&IF($E17="","Falta porcentaje; ","")&IF(N17>1.0001,"Los porcentajes del contrato suman más de 100 %; ","")&IF(AND($C17="Individual",$E17<>"",$E17<>1),"Individual debe ser 100 %; ","")&IF(AND($C17<>"Individual",$C17<>"",$E17=1),"Consorcio o UT con 100 %: revise; ","")&IF(COUNTIFS($A$2:$A$601,$A17,$B$2:$B$601,$B17)>1,"Participación repetida; ","")&IF(AND(IFERROR(INDEX(SUJETOS!$B$2:$B$601,MATCH($B17,SUJETOS!$A$2:$A$601,0)),"")="Persona natural",$G17=""),"Persona natural sin cargo; ","")) | R17: =IF($A17="","",IFERROR(IF(LEN(INDEX(SUJETOS!$F$2:$F$601,MATCH($B17,SUJETOS!$A$2:$A$601,0)))>0,INDEX(SUJETOS!$F$2:$F$601,MATCH($B17,SUJETOS!$A$2:$A$601,0)),$B17),$B17))
... K601: =IF(OR($A601="",$E601=""),"",IFERROR(E601*INDEX(CONTRATOS!$P$2:$P$601,MATCH($A601,CONTRATOS!$A$2:$A$601,0)),"")) | L601: =IF(OR($A601="",$E601=""),"",IFERROR(E601*INDEX(CONTRATOS!$Z$2:$Z$601,MATCH($A601,CONTRATOS!$A$2:$A$601,0)),"")) | M601: =IF(OR($A601="",$E601=""),"",IFERROR(E601*INDEX(CONTRATOS!$AA$2:$AA$601,MATCH($A601,CONTRATOS!$A$2:$A$601,0)),"")) | N601: =IF($A601="","",SUMIFS($E$2:$E$601,$A$2:$A$601,$A601)) | O601: =IF($A601="","",IFERROR(INDEX(CONTRATOS!$F$2:$F$601,MATCH($A601,CONTRATOS!$A$2:$A$601,0)),"")) | P601: =IF($A601="","",IFERROR(INDEX(CONTRATOS!$M$2:$M$601,MATCH($A601,CONTRATOS!$A$2:$A$601,0)),"")) | Q601: =IF($A601="","",IF(COUNTIF(CONTRATOS!$A$2:$A$601,$A601)=0,"El contrato no existe en CONTRATOS; ","")&IF($B601="","Falta sujeto; ",IF(COUNTIF(SUJETOS!$A$2:$A$601,$B601)=0,"El sujeto no existe en SUJETOS; ",""))&IF($E601="","Falta porcentaje; ","")&IF(N601>1.0001,"Los porcentajes del contrato suman más de 100 %; ","")&IF(AND($C601="Individual",$E601<>"",$E601<>1),"Individual debe ser 100 %; ","")&IF(AND($C601<>"Individual",$C601<>"",$E601=1),"Consorcio o UT con 100 %: revise; ","")&IF(COUNTIFS($A$2:$A$601,$A601,$B$2:$B$601,$B601)>1,"Participación repetida; ","")&IF(AND(IFERROR(INDEX(SUJETOS!$B$2:$B$601,MATCH($B601,SUJETOS!$A$2:$A$601,0)),"")="Persona natural",$G601=""),"Persona natural sin cargo; ","")) | R601: =IF($A601="","",IFERROR(IF(LEN(INDEX(SUJETOS!$F$2:$F$601,MATCH($B601,SUJETOS!$A$2:$A$601,0)))>0,INDEX(SUJETOS!$F$2:$F$601,MATCH($B601,SUJETOS!$A$2:$A$601,0)),$B601),$B601))

Sheet UNSPSC
A1: ID_CONTRATO | B1: CODIGO_UNSPSC | C1: DESCRIPCION | D1: SEGMENTO | E1: FAMILIA
